<?xml version="1.0" ?>
<robot xmlns:xacro="http://ros.org/wiki/xacro">
  <xacro:include filename="$(find fanuc_resources)/urdf/common_materials.xacro"/>
  <xacro:include filename="$(find fanuc_resources)/urdf/common_constants.xacro"/>
  <xacro:include filename="$(find fanuc_lrmate200id_support)/urdf/lrmate200id.gazebo.xacro"/>
  <xacro:include filename="$(find fanuc_lrmate200id_support)/urdf/lrmate200id.transmission.xacro"/>
  <!--<xacro:include filename="$(find uos_common_urdf)/common.xacro"/>-->

  <xacro:macro name="fanuc_lrmate200id" params="prefix">
    <link name="${prefix}base_link">
      <visual>
        <origin xyz="0 0 0" rpy="0 0 0"/>
        <geometry>
          <mesh filename="package://fanuc_lrmate200id_support/meshes/lrmate200id/visual/base_link.stl"/>
        </geometry>
        <xacro:material_fanuc_gray28 />
      </visual>
      <collision>
        <origin xyz="0 0 0" rpy="0 0 0"/>
        <geometry>
          <mesh filename="package://fanuc_lrmate200id_support/meshes/lrmate200id/collision/base_link.stl"/>
        </geometry>
      </collision>
      <!--<xacro:box_inertial x="0.19" y=".19" z=".17" mass="4" />-->
      <inertial>
        <mass value="4"/>
        <origin xyz="0 0 0"/>
        <inertia ixx="0.021666658" ixy="0.0" ixz="0.0" iyy="0.021666658" iyz="0.0" izz="0.02406665704"/>
      </inertial>
    </link>
    <link name="${prefix}link_1">
      <visual>
        <origin xyz="0 0 0" rpy="0 0 0"/>
        <geometry>
          <mesh filename="package://fanuc_lrmate200id_support/meshes/lrmate200id/visual/link_1.stl"/>
        </geometry>
        <xacro:material_fanuc_yellow />
      </visual>
      <collision>
        <origin xyz="0 0 0" rpy="0 0 0"/>
        <geometry>
          <mesh filename="package://fanuc_lrmate200id_support/meshes/lrmate200id/collision/link_1.stl"/>
        </geometry>
      </collision>
      <!--<xacro:box_inertial x="0.14" y=".22" z=".22" mass="4" />-->
      <inertial>
        <mass value="4"/>
        <origin xyz="0 0 0"/>
        <inertia ixx="0.03226665376" ixy="0.0" ixz="0.0" iyy="0.0226666576" iyz="0.0" izz="0.0226666576"/>
      </inertial>
    </link>
    <link name="${prefix}link_2">
      <visual>
        <origin xyz="0 0 0" rpy="0 0 0"/>
        <geometry>
          <mesh filename="package://fanuc_lrmate200id_support/meshes/lrmate200id/visual/link_2.stl"/>
        </geometry>
        <xacro:material_fanuc_yellow />
      </visual>
      <collision>
        <origin xyz="0 0 0" rpy="0 0 0"/>
        <geometry>
          <mesh filename="package://fanuc_lrmate200id_support/meshes/lrmate200id/collision/link_2.stl"/>
        </geometry>
      </collision>
      <!--<xacro:box_inertial x="0.14" y=".20" z=".44" mass="5" />-->
      <inertial>
        <mass value="5"/>
        <origin xyz="0 0 0"/>
        <inertia ixx="0.0973332944" ixy="0.0" ixz="0.0" iyy="0.0888332978" iyz="0.0" izz="0.0248333234"/>
      </inertial>
    </link>
    <link name="${prefix}link_3">
      <visual>
        <origin xyz="0 0 0" rpy="0 0 0"/>
        <geometry>
          <mesh filename="package://fanuc_lrmate200id_support/meshes/lrmate200id/visual/link_3.stl"/>
        </geometry>
        <xacro:material_fanuc_yellow />
      </visual>
      <collision>
        <origin xyz="0 0 0" rpy="0 0 0"/>
        <geometry>
          <mesh filename="package://fanuc_lrmate200id_support/meshes/lrmate200id/collision/link_3.stl"/>
        </geometry>
      </collision>
      <!--<xacro:box_inertial x="0.14" y=".12" z=".13" mass="4" />-->
      <inertial>
        <mass value="4"/>
        <origin xyz="0 0 0"/>
        <inertia ixx="0.01043332916" ixy="0.0" ixz="0.0" iyy="0.0121666618" iyz="0.0" izz="0.0113333288"/>
      </inertial>
    </link>
    <link name="${prefix}link_4">
      <visual>
        <origin xyz="0 0 0" rpy="0 0 0"/>
        <geometry>
          <mesh filename="package://fanuc_lrmate200id_support/meshes/lrmate200id/visual/link_4.stl"/>
        </geometry>
        <xacro:material_fanuc_yellow />
      </visual>
      <collision>
        <origin xyz="0 0 0" rpy="0 0 0"/>
        <geometry>
          <mesh filename="package://fanuc_lrmate200id_support/meshes/lrmate200id/collision/link_4.stl"/>
        </geometry>
      </collision>
      <!--<xacro:box_inertial x="0.28" y=".10" z=".10" mass="5" />-->
      <inertial>
        <mass value="5"/>
        <origin xyz="0 0 0"/>
        <inertia ixx="0.00833333" ixy="0.0" ixz="0.0" iyy="0.0368333186" iyz="0.0" izz="0.0368333186"/>
      </inertial>
    </link>
    <link name="${prefix}link_5">
      <visual>
        <origin xyz="0 0 0" rpy="0 0 0"/>
        <geometry>
          <mesh filename="package://fanuc_lrmate200id_support/meshes/lrmate200id/visual/link_5.stl"/>
        </geometry>
        <xacro:material_fanuc_yellow />
      </visual>
      <collision>
        <origin xyz="0 0 0" rpy="0 0 0"/>
        <geometry>
          <mesh filename="package://fanuc_lrmate200id_support/meshes/lrmate200id/collision/link_5.stl"/>
        </geometry>
      </collision>
      <!--<xacro:box_inertial x="0.11" y=".09" z=".08" mass="1.5" />-->
      <inertial>
        <mass value="1.5"/>
        <origin xyz="0 0 0"/>
        <inertia ixx="0.001812499275" ixy="0.0" ixz="0.0" iyy="0.002312499075" iyz="0.0" izz="0.00252499899"/>
      </inertial>
    </link>
    <link name="${prefix}link_6">
      <visual>
        <origin xyz="0 0 0" rpy="0 0 0"/>
        <geometry>
          <mesh filename="package://fanuc_lrmate200id_support/meshes/lrmate200id/visual/link_6.stl"/>
        </geometry>
        <xacro:material_fanuc_black />
      </visual>
      <collision>
        <origin xyz="0 0 0" rpy="0 0 0"/>
        <geometry>
          <mesh filename="package://fanuc_lrmate200id_support/meshes/lrmate200id/collision/link_6.stl"/>
        </geometry>
      </collision>
      <!--<xacro:box_inertial x="0.01" y=".04" z=".04" mass=".25" />-->
      <inertial>
        <mass value="0.25"/>
        <origin xyz="0 0 0"/>
        <inertia ixx="6.666664e-05" ixy="0.0" ixz="0.0" iyy="3.54166525e-05" iyz="0.0" izz="3.54166525e-05"/>
      </inertial>
    </link>
    <link name="${prefix}tool0" />

    <joint name="${prefix}joint_1" type="revolute">
      <origin xyz="0 0 0.330" rpy="0 0 0" />
      <parent link="${prefix}base_link" />
      <child link="${prefix}link_1" />
      <axis xyz="0 0 1" />
      <limit effort="0" lower="-2.965" upper="2.965" velocity="7.85" />
    </joint>
    <joint name="${prefix}joint_2" type="revolute">
      <origin xyz="0.050 0 0" rpy="0 0 0"/>
      <parent link="${prefix}link_1" />
      <child link="${prefix}link_2" />
      <axis xyz="0 1 0" />
      <limit effort="0" lower="-1.745329" upper="2.530727" velocity="6.63" />
    </joint>
    <joint name="${prefix}joint_3" type="revolute">
      <origin xyz="0 0 0.330" rpy="0 0 0"/>
      <parent link="${prefix}link_2" />
      <child link="${prefix}link_3" />
      <axis xyz="0 -1 0" />
      <limit effort="0" lower="-2.450966" upper="4.886922" velocity="9.08" />
    </joint>
    <joint name="${prefix}joint_4" type="revolute">
      <origin xyz="0 0 0.035" rpy="0 0 0"/>
      <parent link="${prefix}link_3"/>
      <child link="${prefix}link_4"/>
      <axis xyz="-1 0 0"/>
      <limit effort="0" lower="-3.315" upper="3.315" velocity="9.60" />
    </joint>
    <joint name="${prefix}joint_5" type="revolute">
      <origin xyz="0.335 0 0" rpy="0 0 0"/>
      <parent link="${prefix}link_4"/>
      <child link="${prefix}link_5"/>
      <axis xyz="0 -1 0"/>
      <limit effort="0" lower="-2.18" upper="2.18" velocity="9.51" />
    </joint>
    <joint name="${prefix}joint_6" type="revolute">
      <origin xyz="0.080 0 0" rpy="0 0 0"/>
      <parent link="${prefix}link_5"/>
      <child link="${prefix}link_6"/>
      <axis xyz="1 0 0"/>
      <limit effort="0" lower="-6.285" upper="6.285" velocity="17.45" />
    </joint>
    <joint name="${prefix}joint_6-tool0" type="fixed">
      <origin xyz="0 0 0" rpy="${m_pi} ${-m_pi_2} 0" />
      <parent link="${prefix}link_6" />
      <child link="${prefix}tool0" />
    </joint>

    <!-- ROS base_link to Fanuc World Coordinates transform -->
    <link name="${prefix}base" />
    <joint name="${prefix}base_link-base" type="fixed">
      <origin xyz="0 0 0.330" rpy="0 0 0"/>
      <parent link="${prefix}base_link"/>
      <child link="${prefix}base"/>
    </joint>
    <xacro:fanuc_transmission prefix="${prefix}"/>
    <xacro:fanuc_gazebo prefix="${prefix}"/>
  </xacro:macro>
</robot>
